2025-10-23 22:21:51,669 - app.services.transcription_service - INFO - TranscriptionService inicializado com modelo: medium
2025-10-23 22:21:51,670 - app.services.ml_model_service - INFO - MLModelService inicializado com modelo: models_data/deviation_classifier.pkl
2025-10-23 22:21:51,670 - app.services.ai_validation_service - WARNING - IA desabilitada: defina ABACUS_API_KEY
2025-10-23 22:21:51,671 - app.services.deviation_classification_service - INFO - DeviationClassificationService inicializado
2025-10-23 22:21:51,674 - app - INFO - CORS configurado para permitir qualquer origem
2025-10-23 22:21:51,675 - app.routes.deviation_routes - INFO - Rotas registradas com sucesso
2025-10-23 22:21:51,675 - app.routes.deviation_routes - INFO - Rotas registradas com sucesso
2025-10-23 22:21:51,680 - app - INFO - Aplicação Flask criada e configurada com sucesso
2025-10-23 22:21:51,681 - app - INFO - Iniciando servidor em 0.0.0.0:8000 (debug=False)
2025-10-23 22:21:55,923 - app.services.transcription_service - INFO - Carregando modelo Faster-Whisper: medium
2025-10-23 22:21:55,923 - app.services.transcription_service - INFO - Carregando modelo Faster-Whisper: medium
2025-10-23 22:22:03,572 - app.services.transcription_service - INFO - Modelo Faster-Whisper carregado com sucesso
2025-10-23 22:22:03,572 - app.services.transcription_service - INFO - Modelo Faster-Whisper carregado com sucesso
2025-10-23 22:22:03,573 - app.services.ml_model_service - INFO - ML carregar: path=models_data/deviation_classifier.pkl
2025-10-23 22:22:03,573 - app.services.ml_model_service - INFO - ML carregar: path=models_data/deviation_classifier.pkl
2025-10-23 22:22:03,575 - app.services.ml_model_service - ERROR - Erro ao carregar modelo ML: Can't get attribute 'MockDeviationClassifier' on <module '__main__' from 'C:\\Users\\hrafa\\OneDrive\\Documentos\\GITHUB\\deviation-classifier-api\\app.py'>
2025-10-23 22:22:03,575 - app.services.ml_model_service - ERROR - Erro ao carregar modelo ML: Can't get attribute 'MockDeviationClassifier' on <module '__main__' from 'C:\\Users\\hrafa\\OneDrive\\Documentos\\GITHUB\\deviation-classifier-api\\app.py'>
2025-10-23 22:23:24,947 - app.services.transcription_service - INFO - TranscriptionService inicializado com modelo: medium
2025-10-23 22:23:24,947 - app.services.ml_model_service - INFO - MLModelService inicializado com modelo: models_data/deviation_classifier.pkl
2025-10-23 22:23:24,948 - app.services.ai_validation_service - INFO - IAValidationService inicializado
2025-10-23 22:23:24,948 - app.services.ai_validation_service - WARNING - IA desabilitada: defina ABACUS_API_KEY
2025-10-23 22:23:24,948 - app.services.deviation_classification_service - INFO - DeviationClassificationService inicializado
2025-10-23 22:23:24,951 - app - INFO - CORS configurado para permitir qualquer origem
2025-10-23 22:23:24,953 - app.routes.deviation_routes - INFO - Rotas registradas com sucesso
2025-10-23 22:23:24,953 - app.routes.deviation_routes - INFO - Rotas registradas com sucesso
2025-10-23 22:23:24,953 - app - INFO - Aplicação Flask criada e configurada com sucesso
2025-10-23 22:23:24,953 - app - INFO - Iniciando servidor em 0.0.0.0:8000 (debug=False)
2025-10-23 22:25:13,147 - app.services.transcription_service - INFO - TranscriptionService inicializado com modelo: medium
2025-10-23 22:25:13,147 - app.services.ml_model_service - INFO - MLModelService inicializado com modelo: models_data/deviation_classifier.pkl
2025-10-23 22:25:13,148 - app.services.ai_validation_service - INFO - IAValidationService inicializado
2025-10-23 22:25:13,148 - app.services.ai_validation_service - INFO - IA pronta (Abacus.AI)
2025-10-23 22:25:13,148 - app.services.deviation_classification_service - INFO - DeviationClassificationService inicializado
2025-10-23 22:25:13,150 - app - INFO - CORS configurado para permitir qualquer origem
2025-10-23 22:25:13,151 - app.routes.deviation_routes - INFO - Rotas registradas com sucesso
2025-10-23 22:25:13,151 - app.routes.deviation_routes - INFO - Rotas registradas com sucesso
2025-10-23 22:25:13,152 - app - INFO - Aplicação Flask criada e configurada com sucesso
2025-10-23 22:25:13,153 - app - INFO - Iniciando servidor em 0.0.0.0:8000 (debug=False)
2025-10-23 22:25:24,204 - app.services.transcription_service - INFO - Carregando modelo Faster-Whisper: medium
2025-10-23 22:25:24,204 - app.services.transcription_service - INFO - Carregando modelo Faster-Whisper: medium
2025-10-23 22:25:31,747 - app.services.transcription_service - INFO - Modelo Faster-Whisper carregado com sucesso
2025-10-23 22:25:31,747 - app.services.transcription_service - INFO - Modelo Faster-Whisper carregado com sucesso
2025-10-23 22:25:31,748 - app.services.ml_model_service - INFO - ML carregar: path=models_data/deviation_classifier.pkl
2025-10-23 22:25:31,748 - app.services.ml_model_service - INFO - ML carregar: path=models_data/deviation_classifier.pkl
2025-10-23 22:25:31,749 - app.services.ml_model_service - ERROR - Erro ao carregar modelo ML: Can't get attribute 'MockDeviationClassifier' on <module '__main__' from 'C:\\Users\\hrafa\\OneDrive\\Documentos\\GITHUB\\deviation-classifier-api\\app.py'>
2025-10-23 22:25:31,749 - app.services.ml_model_service - ERROR - Erro ao carregar modelo ML: Can't get attribute 'MockDeviationClassifier' on <module '__main__' from 'C:\\Users\\hrafa\\OneDrive\\Documentos\\GITHUB\\deviation-classifier-api\\app.py'>
2025-10-23 23:04:10,086 - app.services.transcription_service - INFO - TranscriptionService inicializado com modelo: medium
2025-10-23 23:04:10,087 - app.services.ml_model_service - INFO - MLModelService inicializado com modelo: models_data/deviation_classifier.pkl
2025-10-23 23:04:10,087 - app.services.ai_validation_service - INFO - IAValidationService inicializado
2025-10-23 23:04:10,087 - app.services.ai_validation_service - INFO - IA pronta (Abacus.AI)
2025-10-23 23:04:10,087 - app.services.deviation_classification_service - INFO - DeviationClassificationService inicializado
2025-10-23 23:04:10,180 - app - INFO - CORS configurado para permitir qualquer origem
2025-10-23 23:04:10,185 - app - INFO - Swagger UI configurado em /docs (spec em /swagger.json)
2025-10-23 23:04:10,187 - app.routes.deviation_routes - INFO - Rotas registradas com sucesso
2025-10-23 23:04:10,187 - app.routes.deviation_routes - INFO - Rotas registradas com sucesso
2025-10-23 23:04:10,189 - app - INFO - Aplicação Flask criada e configurada com sucesso
2025-10-23 23:04:10,190 - app - INFO - Iniciando servidor em 0.0.0.0:8000 (debug=False)
2025-10-23 23:04:17,449 - app.services.transcription_service - INFO - Carregando modelo Faster-Whisper: medium
2025-10-23 23:04:17,449 - app.services.transcription_service - INFO - Carregando modelo Faster-Whisper: medium
2025-10-23 23:04:25,451 - app.services.transcription_service - INFO - Modelo Faster-Whisper carregado com sucesso
2025-10-23 23:04:25,451 - app.services.transcription_service - INFO - Modelo Faster-Whisper carregado com sucesso
2025-10-23 23:04:25,453 - app.services.ml_model_service - INFO - ML carregar: path=models_data/deviation_classifier.pkl
2025-10-23 23:04:25,453 - app.services.ml_model_service - INFO - ML carregar: path=models_data/deviation_classifier.pkl
2025-10-23 23:04:25,455 - app.services.ml_model_service - ERROR - Erro ao carregar modelo ML: Can't get attribute 'MockDeviationClassifier' on <module '__main__' from 'C:\\Users\\hrafa\\OneDrive\\Documentos\\GITHUB\\AI_DEVIATION_CLASSIFICATION\\app.py'>
2025-10-23 23:04:25,455 - app.services.ml_model_service - ERROR - Erro ao carregar modelo ML: Can't get attribute 'MockDeviationClassifier' on <module '__main__' from 'C:\\Users\\hrafa\\OneDrive\\Documentos\\GITHUB\\AI_DEVIATION_CLASSIFICATION\\app.py'>
2025-10-23 23:05:27,393 - app.services.ml_model_service - INFO - ML carregar: path=models_data/deviation_classifier.pkl
2025-10-23 23:05:27,393 - app.services.ml_model_service - INFO - ML carregar: path=models_data/deviation_classifier.pkl
2025-10-23 23:05:27,395 - app.services.ml_model_service - ERROR - Erro ao carregar modelo ML: Can't get attribute 'MockDeviationClassifier' on <module '__main__' from 'C:\\Users\\hrafa\\OneDrive\\Documentos\\GITHUB\\AI_DEVIATION_CLASSIFICATION\\app.py'>
2025-10-23 23:05:27,395 - app.services.ml_model_service - ERROR - Erro ao carregar modelo ML: Can't get attribute 'MockDeviationClassifier' on <module '__main__' from 'C:\\Users\\hrafa\\OneDrive\\Documentos\\GITHUB\\AI_DEVIATION_CLASSIFICATION\\app.py'>
2025-10-23 23:05:39,885 - app.services.ml_model_service - INFO - ML carregar: path=models_data/deviation_classifier.pkl
2025-10-23 23:05:39,885 - app.services.ml_model_service - INFO - ML carregar: path=models_data/deviation_classifier.pkl
2025-10-23 23:05:39,889 - app.services.ml_model_service - ERROR - Erro ao carregar modelo ML: Can't get attribute 'MockDeviationClassifier' on <module '__main__' from 'C:\\Users\\hrafa\\OneDrive\\Documentos\\GITHUB\\AI_DEVIATION_CLASSIFICATION\\app.py'>
2025-10-23 23:05:39,889 - app.services.ml_model_service - ERROR - Erro ao carregar modelo ML: Can't get attribute 'MockDeviationClassifier' on <module '__main__' from 'C:\\Users\\hrafa\\OneDrive\\Documentos\\GITHUB\\AI_DEVIATION_CLASSIFICATION\\app.py'>
2025-10-23 23:06:14,554 - app.routes.deviation_routes - ERROR - Erro inesperado: 400 Bad Request: The browser (or proxy) sent a request that this server could not understand.
Traceback (most recent call last):
  File "C:\Users\hrafa\OneDrive\Documentos\GITHUB\AI_DEVIATION_CLASSIFICATION\venv\Lib\site-packages\werkzeug\wrappers\request.py", line 611, in get_json
    rv = self.json_module.loads(data)
  File "C:\Users\hrafa\OneDrive\Documentos\GITHUB\AI_DEVIATION_CLASSIFICATION\venv\Lib\site-packages\flask\json\provider.py", line 188, in loads
    return json.loads(s, **kwargs)
           ~~~~~~~~~~^^^^^^^^^^^^^
  File "C:\Users\hrafa\AppData\Local\Programs\Python\Python313\Lib\json\__init__.py", line 346, in loads
    return _default_decoder.decode(s)
           ~~~~~~~~~~~~~~~~~~~~~~~^^^
  File "C:\Users\hrafa\AppData\Local\Programs\Python\Python313\Lib\json\decoder.py", line 345, in decode
    obj, end = self.raw_decode(s, idx=_w(s, 0).end())
               ~~~~~~~~~~~~~~~^^^^^^^^^^^^^^^^^^^^^^^
  File "C:\Users\hrafa\AppData\Local\Programs\Python\Python313\Lib\json\decoder.py", line 363, in raw_decode
    raise JSONDecodeError("Expecting value", s, err.value) from None
json.decoder.JSONDecodeError: Expecting value: line 1 column 1 (char 0)

During handling of the above exception, another exception occurred:

Traceback (most recent call last):
  File "C:\Users\hrafa\OneDrive\Documentos\GITHUB\AI_DEVIATION_CLASSIFICATION\venv\Lib\site-packages\flask\wrappers.py", line 130, in on_json_loading_failed
    return super().on_json_loading_failed(e)
           ~~~~~~~~~~~~~~~~~~~~~~~~~~~~~~^^^
  File "C:\Users\hrafa\OneDrive\Documentos\GITHUB\AI_DEVIATION_CLASSIFICATION\venv\Lib\site-packages\werkzeug\wrappers\request.py", line 645, in on_json_loading_failed
    raise BadRequest(f"Failed to decode JSON object: {e}")
werkzeug.exceptions.BadRequest: 400 Bad Request: Failed to decode JSON object: Expecting value: line 1 column 1 (char 0)

The above exception was the direct cause of the following exception:

Traceback (most recent call last):
  File "C:\Users\hrafa\OneDrive\Documentos\GITHUB\AI_DEVIATION_CLASSIFICATION\app\routes\deviation_routes.py", line 120, in classify_deviation
    data = request.get_json()
  File "C:\Users\hrafa\OneDrive\Documentos\GITHUB\AI_DEVIATION_CLASSIFICATION\venv\Lib\site-packages\werkzeug\wrappers\request.py", line 620, in get_json
    rv = self.on_json_loading_failed(e)
  File "C:\Users\hrafa\OneDrive\Documentos\GITHUB\AI_DEVIATION_CLASSIFICATION\venv\Lib\site-packages\flask\wrappers.py", line 135, in on_json_loading_failed
    raise BadRequest() from e
werkzeug.exceptions.BadRequest: 400 Bad Request: The browser (or proxy) sent a request that this server could not understand.
2025-10-23 23:06:14,554 - app.routes.deviation_routes - ERROR - Erro inesperado: 400 Bad Request: The browser (or proxy) sent a request that this server could not understand.
Traceback (most recent call last):
  File "C:\Users\hrafa\OneDrive\Documentos\GITHUB\AI_DEVIATION_CLASSIFICATION\venv\Lib\site-packages\werkzeug\wrappers\request.py", line 611, in get_json
    rv = self.json_module.loads(data)
  File "C:\Users\hrafa\OneDrive\Documentos\GITHUB\AI_DEVIATION_CLASSIFICATION\venv\Lib\site-packages\flask\json\provider.py", line 188, in loads
    return json.loads(s, **kwargs)
           ~~~~~~~~~~^^^^^^^^^^^^^
  File "C:\Users\hrafa\AppData\Local\Programs\Python\Python313\Lib\json\__init__.py", line 346, in loads
    return _default_decoder.decode(s)
           ~~~~~~~~~~~~~~~~~~~~~~~^^^
  File "C:\Users\hrafa\AppData\Local\Programs\Python\Python313\Lib\json\decoder.py", line 345, in decode
    obj, end = self.raw_decode(s, idx=_w(s, 0).end())
               ~~~~~~~~~~~~~~~^^^^^^^^^^^^^^^^^^^^^^^
  File "C:\Users\hrafa\AppData\Local\Programs\Python\Python313\Lib\json\decoder.py", line 363, in raw_decode
    raise JSONDecodeError("Expecting value", s, err.value) from None
json.decoder.JSONDecodeError: Expecting value: line 1 column 1 (char 0)

During handling of the above exception, another exception occurred:

Traceback (most recent call last):
  File "C:\Users\hrafa\OneDrive\Documentos\GITHUB\AI_DEVIATION_CLASSIFICATION\venv\Lib\site-packages\flask\wrappers.py", line 130, in on_json_loading_failed
    return super().on_json_loading_failed(e)
           ~~~~~~~~~~~~~~~~~~~~~~~~~~~~~~^^^
  File "C:\Users\hrafa\OneDrive\Documentos\GITHUB\AI_DEVIATION_CLASSIFICATION\venv\Lib\site-packages\werkzeug\wrappers\request.py", line 645, in on_json_loading_failed
    raise BadRequest(f"Failed to decode JSON object: {e}")
werkzeug.exceptions.BadRequest: 400 Bad Request: Failed to decode JSON object: Expecting value: line 1 column 1 (char 0)

The above exception was the direct cause of the following exception:

Traceback (most recent call last):
  File "C:\Users\hrafa\OneDrive\Documentos\GITHUB\AI_DEVIATION_CLASSIFICATION\app\routes\deviation_routes.py", line 120, in classify_deviation
    data = request.get_json()
  File "C:\Users\hrafa\OneDrive\Documentos\GITHUB\AI_DEVIATION_CLASSIFICATION\venv\Lib\site-packages\werkzeug\wrappers\request.py", line 620, in get_json
    rv = self.on_json_loading_failed(e)
  File "C:\Users\hrafa\OneDrive\Documentos\GITHUB\AI_DEVIATION_CLASSIFICATION\venv\Lib\site-packages\flask\wrappers.py", line 135, in on_json_loading_failed
    raise BadRequest() from e
werkzeug.exceptions.BadRequest: 400 Bad Request: The browser (or proxy) sent a request that this server could not understand.
2025-10-23 23:06:22,361 - app.routes.deviation_routes - ERROR - Erro inesperado: 400 Bad Request: The browser (or proxy) sent a request that this server could not understand.
Traceback (most recent call last):
  File "C:\Users\hrafa\OneDrive\Documentos\GITHUB\AI_DEVIATION_CLASSIFICATION\venv\Lib\site-packages\werkzeug\wrappers\request.py", line 611, in get_json
    rv = self.json_module.loads(data)
  File "C:\Users\hrafa\OneDrive\Documentos\GITHUB\AI_DEVIATION_CLASSIFICATION\venv\Lib\site-packages\flask\json\provider.py", line 188, in loads
    return json.loads(s, **kwargs)
           ~~~~~~~~~~^^^^^^^^^^^^^
  File "C:\Users\hrafa\AppData\Local\Programs\Python\Python313\Lib\json\__init__.py", line 346, in loads
    return _default_decoder.decode(s)
           ~~~~~~~~~~~~~~~~~~~~~~~^^^
  File "C:\Users\hrafa\AppData\Local\Programs\Python\Python313\Lib\json\decoder.py", line 345, in decode
    obj, end = self.raw_decode(s, idx=_w(s, 0).end())
               ~~~~~~~~~~~~~~~^^^^^^^^^^^^^^^^^^^^^^^
  File "C:\Users\hrafa\AppData\Local\Programs\Python\Python313\Lib\json\decoder.py", line 363, in raw_decode
    raise JSONDecodeError("Expecting value", s, err.value) from None
json.decoder.JSONDecodeError: Expecting value: line 1 column 1 (char 0)

During handling of the above exception, another exception occurred:

Traceback (most recent call last):
  File "C:\Users\hrafa\OneDrive\Documentos\GITHUB\AI_DEVIATION_CLASSIFICATION\venv\Lib\site-packages\flask\wrappers.py", line 130, in on_json_loading_failed
    return super().on_json_loading_failed(e)
           ~~~~~~~~~~~~~~~~~~~~~~~~~~~~~~^^^
  File "C:\Users\hrafa\OneDrive\Documentos\GITHUB\AI_DEVIATION_CLASSIFICATION\venv\Lib\site-packages\werkzeug\wrappers\request.py", line 645, in on_json_loading_failed
    raise BadRequest(f"Failed to decode JSON object: {e}")
werkzeug.exceptions.BadRequest: 400 Bad Request: Failed to decode JSON object: Expecting value: line 1 column 1 (char 0)

The above exception was the direct cause of the following exception:

Traceback (most recent call last):
  File "C:\Users\hrafa\OneDrive\Documentos\GITHUB\AI_DEVIATION_CLASSIFICATION\app\routes\deviation_routes.py", line 120, in classify_deviation
    data = request.get_json()
  File "C:\Users\hrafa\OneDrive\Documentos\GITHUB\AI_DEVIATION_CLASSIFICATION\venv\Lib\site-packages\werkzeug\wrappers\request.py", line 620, in get_json
    rv = self.on_json_loading_failed(e)
  File "C:\Users\hrafa\OneDrive\Documentos\GITHUB\AI_DEVIATION_CLASSIFICATION\venv\Lib\site-packages\flask\wrappers.py", line 135, in on_json_loading_failed
    raise BadRequest() from e
werkzeug.exceptions.BadRequest: 400 Bad Request: The browser (or proxy) sent a request that this server could not understand.
2025-10-23 23:06:22,361 - app.routes.deviation_routes - ERROR - Erro inesperado: 400 Bad Request: The browser (or proxy) sent a request that this server could not understand.
Traceback (most recent call last):
  File "C:\Users\hrafa\OneDrive\Documentos\GITHUB\AI_DEVIATION_CLASSIFICATION\venv\Lib\site-packages\werkzeug\wrappers\request.py", line 611, in get_json
    rv = self.json_module.loads(data)
  File "C:\Users\hrafa\OneDrive\Documentos\GITHUB\AI_DEVIATION_CLASSIFICATION\venv\Lib\site-packages\flask\json\provider.py", line 188, in loads
    return json.loads(s, **kwargs)
           ~~~~~~~~~~^^^^^^^^^^^^^
  File "C:\Users\hrafa\AppData\Local\Programs\Python\Python313\Lib\json\__init__.py", line 346, in loads
    return _default_decoder.decode(s)
           ~~~~~~~~~~~~~~~~~~~~~~~^^^
  File "C:\Users\hrafa\AppData\Local\Programs\Python\Python313\Lib\json\decoder.py", line 345, in decode
    obj, end = self.raw_decode(s, idx=_w(s, 0).end())
               ~~~~~~~~~~~~~~~^^^^^^^^^^^^^^^^^^^^^^^
  File "C:\Users\hrafa\AppData\Local\Programs\Python\Python313\Lib\json\decoder.py", line 363, in raw_decode
    raise JSONDecodeError("Expecting value", s, err.value) from None
json.decoder.JSONDecodeError: Expecting value: line 1 column 1 (char 0)

During handling of the above exception, another exception occurred:

Traceback (most recent call last):
  File "C:\Users\hrafa\OneDrive\Documentos\GITHUB\AI_DEVIATION_CLASSIFICATION\venv\Lib\site-packages\flask\wrappers.py", line 130, in on_json_loading_failed
    return super().on_json_loading_failed(e)
           ~~~~~~~~~~~~~~~~~~~~~~~~~~~~~~^^^
  File "C:\Users\hrafa\OneDrive\Documentos\GITHUB\AI_DEVIATION_CLASSIFICATION\venv\Lib\site-packages\werkzeug\wrappers\request.py", line 645, in on_json_loading_failed
    raise BadRequest(f"Failed to decode JSON object: {e}")
werkzeug.exceptions.BadRequest: 400 Bad Request: Failed to decode JSON object: Expecting value: line 1 column 1 (char 0)

The above exception was the direct cause of the following exception:

Traceback (most recent call last):
  File "C:\Users\hrafa\OneDrive\Documentos\GITHUB\AI_DEVIATION_CLASSIFICATION\app\routes\deviation_routes.py", line 120, in classify_deviation
    data = request.get_json()
  File "C:\Users\hrafa\OneDrive\Documentos\GITHUB\AI_DEVIATION_CLASSIFICATION\venv\Lib\site-packages\werkzeug\wrappers\request.py", line 620, in get_json
    rv = self.on_json_loading_failed(e)
  File "C:\Users\hrafa\OneDrive\Documentos\GITHUB\AI_DEVIATION_CLASSIFICATION\venv\Lib\site-packages\flask\wrappers.py", line 135, in on_json_loading_failed
    raise BadRequest() from e
werkzeug.exceptions.BadRequest: 400 Bad Request: The browser (or proxy) sent a request that this server could not understand.
2025-10-23 23:06:51,883 - app.routes.deviation_routes - ERROR - Erro inesperado: 400 Bad Request: The browser (or proxy) sent a request that this server could not understand.
Traceback (most recent call last):
  File "C:\Users\hrafa\OneDrive\Documentos\GITHUB\AI_DEVIATION_CLASSIFICATION\venv\Lib\site-packages\werkzeug\wrappers\request.py", line 611, in get_json
    rv = self.json_module.loads(data)
  File "C:\Users\hrafa\OneDrive\Documentos\GITHUB\AI_DEVIATION_CLASSIFICATION\venv\Lib\site-packages\flask\json\provider.py", line 188, in loads
    return json.loads(s, **kwargs)
           ~~~~~~~~~~^^^^^^^^^^^^^
  File "C:\Users\hrafa\AppData\Local\Programs\Python\Python313\Lib\json\__init__.py", line 346, in loads
    return _default_decoder.decode(s)
           ~~~~~~~~~~~~~~~~~~~~~~~^^^
  File "C:\Users\hrafa\AppData\Local\Programs\Python\Python313\Lib\json\decoder.py", line 345, in decode
    obj, end = self.raw_decode(s, idx=_w(s, 0).end())
               ~~~~~~~~~~~~~~~^^^^^^^^^^^^^^^^^^^^^^^
  File "C:\Users\hrafa\AppData\Local\Programs\Python\Python313\Lib\json\decoder.py", line 363, in raw_decode
    raise JSONDecodeError("Expecting value", s, err.value) from None
json.decoder.JSONDecodeError: Expecting value: line 1 column 1 (char 0)

During handling of the above exception, another exception occurred:

Traceback (most recent call last):
  File "C:\Users\hrafa\OneDrive\Documentos\GITHUB\AI_DEVIATION_CLASSIFICATION\venv\Lib\site-packages\flask\wrappers.py", line 130, in on_json_loading_failed
    return super().on_json_loading_failed(e)
           ~~~~~~~~~~~~~~~~~~~~~~~~~~~~~~^^^
  File "C:\Users\hrafa\OneDrive\Documentos\GITHUB\AI_DEVIATION_CLASSIFICATION\venv\Lib\site-packages\werkzeug\wrappers\request.py", line 645, in on_json_loading_failed
    raise BadRequest(f"Failed to decode JSON object: {e}")
werkzeug.exceptions.BadRequest: 400 Bad Request: Failed to decode JSON object: Expecting value: line 1 column 1 (char 0)

The above exception was the direct cause of the following exception:

Traceback (most recent call last):
  File "C:\Users\hrafa\OneDrive\Documentos\GITHUB\AI_DEVIATION_CLASSIFICATION\app\routes\deviation_routes.py", line 120, in classify_deviation
    data = request.get_json()
  File "C:\Users\hrafa\OneDrive\Documentos\GITHUB\AI_DEVIATION_CLASSIFICATION\venv\Lib\site-packages\werkzeug\wrappers\request.py", line 620, in get_json
    rv = self.on_json_loading_failed(e)
  File "C:\Users\hrafa\OneDrive\Documentos\GITHUB\AI_DEVIATION_CLASSIFICATION\venv\Lib\site-packages\flask\wrappers.py", line 135, in on_json_loading_failed
    raise BadRequest() from e
werkzeug.exceptions.BadRequest: 400 Bad Request: The browser (or proxy) sent a request that this server could not understand.
2025-10-23 23:06:51,883 - app.routes.deviation_routes - ERROR - Erro inesperado: 400 Bad Request: The browser (or proxy) sent a request that this server could not understand.
Traceback (most recent call last):
  File "C:\Users\hrafa\OneDrive\Documentos\GITHUB\AI_DEVIATION_CLASSIFICATION\venv\Lib\site-packages\werkzeug\wrappers\request.py", line 611, in get_json
    rv = self.json_module.loads(data)
  File "C:\Users\hrafa\OneDrive\Documentos\GITHUB\AI_DEVIATION_CLASSIFICATION\venv\Lib\site-packages\flask\json\provider.py", line 188, in loads
    return json.loads(s, **kwargs)
           ~~~~~~~~~~^^^^^^^^^^^^^
  File "C:\Users\hrafa\AppData\Local\Programs\Python\Python313\Lib\json\__init__.py", line 346, in loads
    return _default_decoder.decode(s)
           ~~~~~~~~~~~~~~~~~~~~~~~^^^
  File "C:\Users\hrafa\AppData\Local\Programs\Python\Python313\Lib\json\decoder.py", line 345, in decode
    obj, end = self.raw_decode(s, idx=_w(s, 0).end())
               ~~~~~~~~~~~~~~~^^^^^^^^^^^^^^^^^^^^^^^
  File "C:\Users\hrafa\AppData\Local\Programs\Python\Python313\Lib\json\decoder.py", line 363, in raw_decode
    raise JSONDecodeError("Expecting value", s, err.value) from None
json.decoder.JSONDecodeError: Expecting value: line 1 column 1 (char 0)

During handling of the above exception, another exception occurred:

Traceback (most recent call last):
  File "C:\Users\hrafa\OneDrive\Documentos\GITHUB\AI_DEVIATION_CLASSIFICATION\venv\Lib\site-packages\flask\wrappers.py", line 130, in on_json_loading_failed
    return super().on_json_loading_failed(e)
           ~~~~~~~~~~~~~~~~~~~~~~~~~~~~~~^^^
  File "C:\Users\hrafa\OneDrive\Documentos\GITHUB\AI_DEVIATION_CLASSIFICATION\venv\Lib\site-packages\werkzeug\wrappers\request.py", line 645, in on_json_loading_failed
    raise BadRequest(f"Failed to decode JSON object: {e}")
werkzeug.exceptions.BadRequest: 400 Bad Request: Failed to decode JSON object: Expecting value: line 1 column 1 (char 0)

The above exception was the direct cause of the following exception:

Traceback (most recent call last):
  File "C:\Users\hrafa\OneDrive\Documentos\GITHUB\AI_DEVIATION_CLASSIFICATION\app\routes\deviation_routes.py", line 120, in classify_deviation
    data = request.get_json()
  File "C:\Users\hrafa\OneDrive\Documentos\GITHUB\AI_DEVIATION_CLASSIFICATION\venv\Lib\site-packages\werkzeug\wrappers\request.py", line 620, in get_json
    rv = self.on_json_loading_failed(e)
  File "C:\Users\hrafa\OneDrive\Documentos\GITHUB\AI_DEVIATION_CLASSIFICATION\venv\Lib\site-packages\flask\wrappers.py", line 135, in on_json_loading_failed
    raise BadRequest() from e
werkzeug.exceptions.BadRequest: 400 Bad Request: The browser (or proxy) sent a request that this server could not understand.
